
2022-06-18 16:38:20,893 Downloading and reading test artifact
2022-06-18 16:38:27,793 Extracting target from dataframe
2022-06-18 16:38:27,795 Downloading and reading the exported model
[34m[1mwandb[39m[22m: [32m[41mERROR[39m[49m Attempted to fetch artifact without alias (e.g. "<artifact_name>:v3" or "<artifact_name>:latest")
Traceback (most recent call last):
  File "/Users/ivopdm/.conda/envs/mlflow-f8b5853f2b26bd5a901af33dedeb16cab984e515/lib/python3.8/site-packages/wandb/apis/public.py", line 4069, in _load
    response = self.client.execute(
  File "/Users/ivopdm/.conda/envs/mlflow-f8b5853f2b26bd5a901af33dedeb16cab984e515/lib/python3.8/site-packages/wandb/sdk/lib/retry.py", line 159, in wrapped_fn
    return retrier(*args, **kargs)
  File "/Users/ivopdm/.conda/envs/mlflow-f8b5853f2b26bd5a901af33dedeb16cab984e515/lib/python3.8/site-packages/wandb/sdk/lib/retry.py", line 102, in __call__
    result = self._call_fn(*args, **kwargs)
  File "/Users/ivopdm/.conda/envs/mlflow-f8b5853f2b26bd5a901af33dedeb16cab984e515/lib/python3.8/site-packages/wandb/apis/public.py", line 204, in execute
    return self._client.execute(*args, **kwargs)
  File "/Users/ivopdm/.conda/envs/mlflow-f8b5853f2b26bd5a901af33dedeb16cab984e515/lib/python3.8/site-packages/wandb/vendor/gql-0.2.0/wandb_gql/client.py", line 52, in execute
    result = self._get_result(document, *args, **kwargs)
  File "/Users/ivopdm/.conda/envs/mlflow-f8b5853f2b26bd5a901af33dedeb16cab984e515/lib/python3.8/site-packages/wandb/vendor/gql-0.2.0/wandb_gql/client.py", line 60, in _get_result
    return self.transport.execute(document, *args, **kwargs)
  File "/Users/ivopdm/.conda/envs/mlflow-f8b5853f2b26bd5a901af33dedeb16cab984e515/lib/python3.8/site-packages/wandb/vendor/gql-0.2.0/wandb_gql/transport/requests.py", line 39, in execute
    request.raise_for_status()
  File "/Users/ivopdm/.conda/envs/mlflow-f8b5853f2b26bd5a901af33dedeb16cab984e515/lib/python3.8/site-packages/requests/models.py", line 1022, in raise_for_status
    raise HTTPError(http_error_msg, response=self)
requests.exceptions.HTTPError: 400 Client Error: Bad Request for url: https://api.wandb.ai/graphql
During handling of the above exception, another exception occurred:
Traceback (most recent call last):
  File "/Users/ivopdm/.conda/envs/mlflow-f8b5853f2b26bd5a901af33dedeb16cab984e515/lib/python3.8/site-packages/wandb/apis/normalize.py", line 22, in wrapper
    return func(*args, **kwargs)
  File "/Users/ivopdm/.conda/envs/mlflow-f8b5853f2b26bd5a901af33dedeb16cab984e515/lib/python3.8/site-packages/wandb/apis/public.py", line 791, in artifact
    artifact = Artifact(self.client, entity, project, artifact_name)
  File "/Users/ivopdm/.conda/envs/mlflow-f8b5853f2b26bd5a901af33dedeb16cab984e515/lib/python3.8/site-packages/wandb/apis/public.py", line 3518, in __init__
    self._load()
  File "/Users/ivopdm/.conda/envs/mlflow-f8b5853f2b26bd5a901af33dedeb16cab984e515/lib/python3.8/site-packages/wandb/apis/public.py", line 4081, in _load
    raise ValueError(
ValueError: Attempted to fetch artifact without alias (e.g. "<artifact_name>:v3" or "<artifact_name>:latest")
During handling of the above exception, another exception occurred:
Traceback (most recent call last):
  File "run.py", line 87, in <module>
    go(args)
  File "run.py", line 32, in go
    model_export_path = run.use_artifact(args.model_export).download("./artifacts/model_export_v0")
  File "/Users/ivopdm/.conda/envs/mlflow-f8b5853f2b26bd5a901af33dedeb16cab984e515/lib/python3.8/site-packages/wandb/sdk/wandb_run.py", line 222, in wrapper
    return func(self, *args, **kwargs)
  File "/Users/ivopdm/.conda/envs/mlflow-f8b5853f2b26bd5a901af33dedeb16cab984e515/lib/python3.8/site-packages/wandb/sdk/wandb_run.py", line 2308, in use_artifact
    artifact = public_api.artifact(type=type, name=name)
  File "/Users/ivopdm/.conda/envs/mlflow-f8b5853f2b26bd5a901af33dedeb16cab984e515/lib/python3.8/site-packages/wandb/apis/normalize.py", line 58, in wrapper
    raise CommError(message, err).with_traceback(sys.exc_info()[2])
  File "/Users/ivopdm/.conda/envs/mlflow-f8b5853f2b26bd5a901af33dedeb16cab984e515/lib/python3.8/site-packages/wandb/apis/normalize.py", line 22, in wrapper
    return func(*args, **kwargs)
  File "/Users/ivopdm/.conda/envs/mlflow-f8b5853f2b26bd5a901af33dedeb16cab984e515/lib/python3.8/site-packages/wandb/apis/public.py", line 791, in artifact
    artifact = Artifact(self.client, entity, project, artifact_name)
  File "/Users/ivopdm/.conda/envs/mlflow-f8b5853f2b26bd5a901af33dedeb16cab984e515/lib/python3.8/site-packages/wandb/apis/public.py", line 3518, in __init__
    self._load()
  File "/Users/ivopdm/.conda/envs/mlflow-f8b5853f2b26bd5a901af33dedeb16cab984e515/lib/python3.8/site-packages/wandb/apis/public.py", line 4081, in _load
    raise ValueError(
wandb.errors.CommError: Attempted to fetch artifact without alias (e.g. "<artifact_name>:v3" or "<artifact_name>:latest")